Workbook

Sheet Станд.норм.распр.
A1: Эксперимент | B1: 1 | C1: 2 | D1: 3 | E1: 4 | F1: 5 | G1: 6 | H1: 7 | I1: 8 | J1: 9 | K1: 10
A3: u 1 | B3: -0.028117029 | C3: -1.7017146 | D3: -0.54151542 | E3: 0.39923748 | F3: -0.94007953 | G3: 0.38157054 | H3: 0.88259867 | I3: -2.1222695 | J3: 0.81152166 | K3: -0.94664074
A4: u 2 | B4: -0.13377303 | C4: 2.0590323 | D4: 2.0433617 | E4: 1.3031877 | F4: 0.7844892 | G4: -0.91560423 | H4: -0.85754288 | I4: 0.65159156 | J4: 0.046873083 | K4: 0.70356464
A5: u 3 | B5: -0.63859375 | C5: -0.3852756 | D5: 0.93473318 | E5: 2.0791958 | F5: 0.37335553 | G5: -0.051544475 | H5: 1.2979914 | I5: -1.1267821 | J5: -1.0132885 | K5: -0.70180135
A6: u 4 | B6: -0.8930374 | C6: 2.1438609 | D6: -0.027810074 | E6: -0.3047171 | F6: 0.31965556 | G6: 0.29152034 | H6: 2.2457425 | I6: 0.31057198 | J6: 0.068787358 | K6: 0.044192348
A7: u 5 | B7: 0.0040154191 | C7: 0.06924779 | D7: 0.46304763 | E7: -0.036918664 | F7: 0.21292522 | G7: -0.088125489 | H7: -0.26654561 | I7: 0.36655592 | J7: 0.042481017 | K7: 1.5348496
A8: u 6 | B8: -0.82779252 | C8: -1.8222136 | D8: 0.5788354 | E8: -0.94233883 | F8: 0.60233333 | G8: 0.19098593 | H8: -0.20940547 | I8: -0.79693336 | J8: -0.84111889 | K8: 0.91711854
A9: u 7 | B9: 1.2953592 | C9: -0.9172345 | D9: 0.90196181 | E9: 1.1392831 | F9: 0.25269969 | G9: -0.072699322 | H9: 0.57612397 | I9: 0.61587002 | J9: 0.7434187 | K9: 0.19737854
A10: u 8 | B10: 0.33288757 | C10: -2.1625056 | D10: -0.72717967 | E10: 0.44566036 | F10: 0.024519977 | G10: 1.8059563 | H10: 1.3853037 | I10: 0.2911213 | J10: 0.83073098 | K10: -1.1263501
A11: u 9 | B11: 0.69564976 | C11: -0.27535407 | D11: -0.67283395 | E11: 0.0439627 | F11: -0.24567612 | G11: 1.0691952 | H11: 1.3251383 | I11: 0.79756546 | J11: 1.13243 | K11: 0.34276809
A12: u 10 | B12: 0.26551561 | C12: -2.1453798 | D12: 0.51032885 | E12: 1.5016667 | F12: 0.57170382 | G12: 0.92765276 | H12: 2.5883492 | I12: 1.1947486 | J12: 0.095346877 | K12: -0.29367584
A13: u 11 | B13: -0.2355182 | C13: -0.946402 | D13: -0.064801498 | E13: -0.58345449 | F13: 0.55199735 | G13: -0.85239662 | H13: 0.21167352 | I13: 2.4379551 | J13: -0.4101139 | K13: -0.12536475
... A102: u 100 | B102: 1.6609 | C102: -0.22880272 | D102: -1.8118356 | E102: 1.4537984 | F102: -1.1155979 | G102: -0.93441155 | H102: 0.96174753 | I102: 0.12693101 | J102: -1.722188 | K102: 0.32271381

Sheet Задание
A1: Спецификация | B1: Y=а0+а1*X | I1: Провести расчеты для каждого из случаев:
A2: а0= | B2: 5 | C2: X1 | D2: = | E2: 212 | F2: Y1 | G2: = | H2: =E2*$B$3+$B$2+RAND()*$B$4 -> 1491.6157 | J2: а. Выполнение всех предпосылок теоремы Гаусса-Маркова
A3: а1= | B3: 7 | C3: X2 | D3: = | E3: 780 | G3: = | H3: =E3*$B$3+$B$2+RAND()*$B$4 -> 5467.1223 | J3: б. Нарушение предпосылки о нулевом математическом ожидании остатков
A4: сигма= | B4: 3 | C4: X3 | D4: = | E4: 280 | G4: = | H4: =E4*$B$3+$B$2+RAND()*$B$4 -> 1965.164 | J4: в. Нарушение предпосылки о гомоскедастичности остатков
C5: X4 | D5: = | E5: 888 | G5: = | H5: =E5*$B$3+$B$2+RAND()*$B$4 -> 6222.9841 | J5: г. Нарушение предпосылки о некоррелированности остатков
C6: X5 | D6: = | E6: 314 | G6: = | H6: =E6*$B$3+$B$2+RAND()*$B$4 -> 2205.9248 | J6: д. Нарушение предпосылки о некоррелированности значений экзогенной переменной и остатков
C7: X6 | D7: = | E7: 780 | G7: = | H7: =E7*$B$3+$B$2+RAND()*$B$4 -> 5466.6745
C8: X7 | D8: = | E8: 993 | G8: = | H8: =E8*$B$3+$B$2+RAND()*$B$4 -> 6956.8781 | I8: 1. Записать на основе функциональной зависимости спецификацию корреляционной зависимости с требуемыми характеристиками
C9: X8 | D9: = | E9: 326 | G9: = | H9: =E9*$B$3+$B$2+RAND()*$B$4 -> 2287.2274 | I9: 2. Имитировать данные для оценивания методом статистических испытаний Монте-Карло и на их основе оценить параметры модели
C10: X9 | D10: = | E10: 906 | G10: = | H10: =E10*$B$3+$B$2+RAND()*$B$4 -> 6349.0646 | I10: 3. Проанализровать результаты оценивания параметров модели и написать вывод
C11: X10 | D11: = | E11: 790 | G11: = | H11: =E11*$B$3+$B$2+RAND()*$B$4 -> 5535.521
C12: X11 | D12: = | E12: 127 | G12: = | H12: =E12*$B$3+$B$2+RAND()*$B$4 -> 894.16978
C13: X12 | D13: = | E13: 685 | G13: = | H13: =E13*$B$3+$B$2+RAND()*$B$4 -> 4802.0617
C14: X13 | D14: = | E14: 320 | G14: = | H14: =E14*$B$3+$B$2+RAND()*$B$4 -> 2246.2249 | I14: Примечание:
C15: X14 | D15: = | E15: 658 | G15: = | H15: =E15*$B$3+$B$2+RAND()*$B$4 -> 4611.5927 | I15: В каждом случае провести 10 экспериментов.
C16: X15 | D16: = | E16: 436 | G16: = | H16: =E16*$B$3+$B$2+RAND()*$B$4 -> 3059.2502 | I16: Расчеты для каждого пункта выполнить на отдельном листе.
C17: X16 | D17: = | E17: 686 | G17: = | H17: =E17*$B$3+$B$2+RAND()*$B$4 -> 4808.6637
C18: X17 | D18: = | E18: 797 | G18: = | H18: =E18*$B$3+$B$2+RAND()*$B$4 -> 5585.2181
C19: X18 | D19: = | E19: 464 | G19: = | H19: =E19*$B$3+$B$2+RAND()*$B$4 -> 3254.0153
C20: X19 | D20: = | E20: 514 | G20: = | H20: =E20*$B$3+$B$2+RAND()*$B$4 -> 3605.5046
C21: X20 | D21: = | E21: 724 | G21: = | H21: =E21*$B$3+$B$2+RAND()*$B$4 -> 5075.4202
C22: X21 | D22: = | E22: 63 | G22: = | H22: =E22*$B$3+$B$2+RAND()*$B$4 -> 447.99895
C23: X22 | D23: = | E23: 298 | G23: = | H23: =E23*$B$3+$B$2+RAND()*$B$4 -> 2093.3637
C24: X23 | D24: = | E24: 689 | G24: = | H24: =E24*$B$3+$B$2+RAND()*$B$4 -> 4828.3955
C25: X24 | D25: = | E25: 278 | G25: = | H25: =E25*$B$3+$B$2+RAND()*$B$4 -> 1951.5009
C26: X25 | D26: = | E26: 701 | G26: = | H26: =E26*$B$3+$B$2+RAND()*$B$4 -> 4913.9026
C27: X26 | D27: = | E27: 219 | G27: = | H27: =E27*$B$3+$B$2+RAND()*$B$4 -> 1540.0854
C28: X27 | D28: = | E28: 666 | G28: = | H28: =E28*$B$3+$B$2+RAND()*$B$4 -> 4669.4163
... C101: X100 | D101: = | E101: 629 | G101: = | H101: =E101*$B$3+$B$2+RAND()*$B$4 -> 4410.0127

Sheet 1.
A1: Ui = ui * сигма
E2: 1 | H2: 2 | K2: 3 | N2: 4 | Q2: 5 | T2: 6 | W2: 7 | Z2: 8 | AC2: 9 | AF2: 10
E3: {=LINEST(H$10:H$109,$E$10:$E$109,1,1)} -> 1.0007359 | F3: 1.6085051 | H3: {=LINEST(I$10:I$109,$E$10:$E$109,1,1)} -> 1.0001409 | I3: 1.9250225 | K3: {=LINEST(J$10:J$109,$E$10:$E$109,1,1)} -> 0.99948982 | L3: 2.2714189 | N3: {=LINEST(K$10:K$109,$E$10:$E$109,1,1)} -> 0.99856222 | O3: 2.7649155 | Q3: {=LINEST(L$10:L$109,$E$10:$E$109,1,1)} -> 0.99958779 | R3: 2.2193005 | T3: {=LINEST(M$10:M$109,$E$10:$E$109,1,1)} -> 0.99815911 | U3: 2.9793717 | W3: {=LINEST(N$10:N$109,$E$10:$E$109,1,1)} -> 1.0003619 | X3: 1.8074585 | Z3: {=LINEST(O$10:O$109,$E$10:$E$109,1,1)} -> 0.99990494 | AA3: 2.0505734 | AC3: {=LINEST(P$10:P$109,$E$10:$E$109,1,1)} -> 1.0008826 | AD3: 1.5304399 | AF3: {=LINEST(Q$10:Q$109,$E$10:$E$109,1,1)} -> 0.99966953 | AG3: 2.1758119
E4: 0.00095820679 | F4: 0.57393678 | H4: 0.0011748164 | I4: 0.70367937 | K4: 0.0011386948 | L4: 0.68204364 | N4: 0.00096504595 | O4: 0.57803323 | Q4: 0.00094755799 | R4: 0.56755847 | T4: 0.0010215504 | U4: 0.61187768 | W4: 0.0011429048 | X4: 0.68456531 | Z4: 0.0011637727 | AA4: 0.69706452 | AC4: 0.00094139675 | AD4: 0.56386807 | AF4: 0.00093863998 | AG4: 0.56221685
E5: 0.99991016 | F5: 2.6368972 | H5: 0.9998648 | I5: 3.232987 | K5: 0.99987282 | L5: 3.1335837 | N5: 0.99990848 | O5: 2.6557179 | Q5: 0.99991194 | R5: 2.6075927 | T5: 0.99989736 | U5: 2.811213 | W5: 0.9998721 | X5: 3.1451693 | Z5: 0.99986726 | AA5: 3.2025957 | AC5: 0.99991331 | AD5: 2.5906375 | AF5: 0.99991361 | AG5: 2.5830511
E6: 1090738 | F6: 98 | H6: 724740.25 | I6: 98 | K6: 770445.72 | L6: 98 | N6: 1070666.6 | O6: 98 | Q6: 1112833.7 | R6: 98 | T6: 954728.63 | U6: 98 | W6: 766115.32 | X6: 98 | Z6: 738211.98 | AA6: 98 | AC6: 1130370.7 | AD6: 98 | AF6: 1134265.7 | AG6: 98
E7: 7584148.7 | F7: 681.41621 | H7: 7575133.7 | I7: 1024.3161 | K7: 7565273.8 | L7: 962.29601 | N7: 7551238 | O7: 691.17809 | Q7: 7566756.9 | R7: 666.35487 | T7: 7545142.5 | U7: 774.48601 | W7: 7578481.5 | X7: 969.4248 | Z7: 7571559.3 | AA7: 1005.1487 | AC7: 7586373 | AD7: 657.71745 | AF7: 7567994.6 | AG7: 653.87099
E8: =ABS(F3)/F4 -> 2.8025823 | F8: =F7/(E7/F6) -> 0.0088050474 | H8: =ABS(I3)/I4 -> 2.7356529 | I8: =I7/(H7/I6) -> 0.013251644 | K8: =ABS(L3)/L4 -> 3.3303131 | L8: =L7/(K7/L6) -> 0.012465512 | N8: =ABS(O3)/O4 -> 4.7833159 | O8: =O7/(N7/O6) -> 0.0089701123 | Q8: =ABS(R3)/R4 -> 3.9102587 | R8: =R7/(Q7/R6) -> 0.00863022 | T8: =ABS(U3)/U4 -> 4.8692276 | U8: =U7/(T7/U6) -> 0.010059403 | W8: =ABS(X3)/X4 -> 2.640301 | X8: =X7/(W7/X6) -> 0.012535972 | Z8: =ABS(AA3)/AA4 -> 2.9417268 | AA8: =AA7/(Z7/AA6) -> 0.013009813 | AC8: =ABS(AD3)/AD4 -> 2.7141808 | AD8: =AD7/(AC7/AD6) -> 0.0084963276 | AF8: =ABS(AG3)/AG4 -> 3.8700582 | AG8: =AG7/(AF7/AG6) -> 0.0084671516
A9: Спецификация | B9: Y=а0+а1*X | H9: 1 | I9: 2 | J9: 3 | K9: 4 | L9: 5 | M9: 6 | N9: 7 | O9: 8 | P9: 9 | Q9: 10
A10: а0= | B10: 2 | C10: X1 | D10: = | E10: 212 | F10: Y1 | G10: = | H10: =$E10*$B$11+$B$10+'Станд.норм.распр.'!B3*$B$12 -> 213.91565 | I10: =$E10*$B$11+$B$10+'Станд.норм.распр.'!C3*$B$12 -> 208.89486 | J10: =$E10*$B$11+$B$10+'Станд.норм.распр.'!D3*$B$12 -> 212.37545 | K10: =$E10*$B$11+$B$10+'Станд.норм.распр.'!E3*$B$12 -> 215.19771 | L10: =$E10*$B$11+$B$10+'Станд.норм.распр.'!F3*$B$12 -> 211.17976 | M10: =$E10*$B$11+$B$10+'Станд.норм.распр.'!G3*$B$12 -> 215.14471 | N10: =$E10*$B$11+$B$10+'Станд.норм.распр.'!H3*$B$12 -> 216.6478 | O10: =$E10*$B$11+$B$10+'Станд.норм.распр.'!I3*$B$12 -> 207.63319 | ... Q10: =$E10*$B$11+$B$10+'Станд.норм.распр.'!K3*$B$12 -> 211.16008
A11: а1= | B11: 1 | C11: X2 | D11: = | E11: 780 | G11: = | H11: =$E11*$B$11+$B$10+'Станд.норм.распр.'!B4*$B$12 -> 781.59868 | I11: =$E11*$B$11+$B$10+'Станд.норм.распр.'!C4*$B$12 -> 788.1771 | J11: =$E11*$B$11+$B$10+'Станд.норм.распр.'!D4*$B$12 -> 788.13009 | K11: =$E11*$B$11+$B$10+'Станд.норм.распр.'!E4*$B$12 -> 785.90956 | L11: =$E11*$B$11+$B$10+'Станд.норм.распр.'!F4*$B$12 -> 784.35347 | M11: =$E11*$B$11+$B$10+'Станд.норм.распр.'!G4*$B$12 -> 779.25319 | N11: =$E11*$B$11+$B$10+'Станд.норм.распр.'!H4*$B$12 -> 779.42737 | O11: =$E11*$B$11+$B$10+'Станд.норм.распр.'!I4*$B$12 -> 783.95477 | ... Q11: =$E11*$B$11+$B$10+'Станд.норм.распр.'!K4*$B$12 -> 784.11069
A12: сигма= | B12: 3 | C12: X3 | D12: = | E12: 280 | G12: = | H12: =$E12*$B$11+$B$10+'Станд.норм.распр.'!B5*$B$12 -> 280.08422 | I12: =$E12*$B$11+$B$10+'Станд.норм.распр.'!C5*$B$12 -> 280.84417 | J12: =$E12*$B$11+$B$10+'Станд.норм.распр.'!D5*$B$12 -> 284.8042 | K12: =$E12*$B$11+$B$10+'Станд.норм.распр.'!E5*$B$12 -> 288.23759 | L12: =$E12*$B$11+$B$10+'Станд.норм.распр.'!F5*$B$12 -> 283.12007 | M12: =$E12*$B$11+$B$10+'Станд.норм.распр.'!G5*$B$12 -> 281.84537 | N12: =$E12*$B$11+$B$10+'Станд.норм.распр.'!H5*$B$12 -> 285.89397 | O12: =$E12*$B$11+$B$10+'Станд.норм.распр.'!I5*$B$12 -> 278.61965 | ... Q12: =$E12*$B$11+$B$10+'Станд.норм.распр.'!K5*$B$12 -> 279.8946
C13: X4 | D13: = | E13: 888 | G13: = | H13: =$E13*$B$11+$B$10+'Станд.норм.распр.'!B6*$B$12 -> 887.32089 | I13: =$E13*$B$11+$B$10+'Станд.норм.распр.'!C6*$B$12 -> 896.43158 | J13: =$E13*$B$11+$B$10+'Станд.норм.распр.'!D6*$B$12 -> 889.91657 | K13: =$E13*$B$11+$B$10+'Станд.норм.распр.'!E6*$B$12 -> 889.08585 | L13: =$E13*$B$11+$B$10+'Станд.норм.распр.'!F6*$B$12 -> 890.95897 | M13: =$E13*$B$11+$B$10+'Станд.норм.распр.'!G6*$B$12 -> 890.87456 | N13: =$E13*$B$11+$B$10+'Станд.норм.распр.'!H6*$B$12 -> 896.73723 | O13: =$E13*$B$11+$B$10+'Станд.норм.распр.'!I6*$B$12 -> 890.93172 | ... Q13: =$E13*$B$11+$B$10+'Станд.норм.распр.'!K6*$B$12 -> 890.13258
C14: X5 | D14: = | E14: 314 | G14: = | H14: =$E14*$B$11+$B$10+'Станд.норм.распр.'!B7*$B$12 -> 316.01205 | I14: =$E14*$B$11+$B$10+'Станд.норм.распр.'!C7*$B$12 -> 316.20774 | J14: =$E14*$B$11+$B$10+'Станд.норм.распр.'!D7*$B$12 -> 317.38914 | K14: =$E14*$B$11+$B$10+'Станд.норм.распр.'!E7*$B$12 -> 315.88924 | L14: =$E14*$B$11+$B$10+'Станд.норм.распр.'!F7*$B$12 -> 316.63878 | M14: =$E14*$B$11+$B$10+'Станд.норм.распр.'!G7*$B$12 -> 315.73562 | N14: =$E14*$B$11+$B$10+'Станд.норм.распр.'!H7*$B$12 -> 315.20036 | O14: =$E14*$B$11+$B$10+'Станд.норм.распр.'!I7*$B$12 -> 317.09967 | ... Q14: =$E14*$B$11+$B$10+'Станд.норм.распр.'!K7*$B$12 -> 320.60455
C15: X6 | D15: = | E15: 780 | G15: = | H15: =$E15*$B$11+$B$10+'Станд.норм.распр.'!B8*$B$12 -> 779.51662 | I15: =$E15*$B$11+$B$10+'Станд.норм.распр.'!C8*$B$12 -> 776.53336 | J15: =$E15*$B$11+$B$10+'Станд.норм.распр.'!D8*$B$12 -> 783.73651 | K15: =$E15*$B$11+$B$10+'Станд.норм.распр.'!E8*$B$12 -> 779.17298 | L15: =$E15*$B$11+$B$10+'Станд.норм.распр.'!F8*$B$12 -> 783.807 | M15: =$E15*$B$11+$B$10+'Станд.норм.распр.'!G8*$B$12 -> 782.57296 | N15: =$E15*$B$11+$B$10+'Станд.норм.распр.'!H8*$B$12 -> 781.37178 | O15: =$E15*$B$11+$B$10+'Станд.норм.распр.'!I8*$B$12 -> 779.6092 | ... Q15: =$E15*$B$11+$B$10+'Станд.норм.распр.'!K8*$B$12 -> 784.75136
C16: X7 | D16: = | E16: 993 | G16: = | H16: =$E16*$B$11+$B$10+'Станд.норм.распр.'!B9*$B$12 -> 998.88608 | I16: =$E16*$B$11+$B$10+'Станд.норм.распр.'!C9*$B$12 -> 992.2483 | J16: =$E16*$B$11+$B$10+'Станд.норм.распр.'!D9*$B$12 -> 997.70589 | K16: =$E16*$B$11+$B$10+'Станд.норм.распр.'!E9*$B$12 -> 998.41785 | L16: =$E16*$B$11+$B$10+'Станд.норм.распр.'!F9*$B$12 -> 995.7581 | M16: =$E16*$B$11+$B$10+'Станд.норм.распр.'!G9*$B$12 -> 994.7819 | N16: =$E16*$B$11+$B$10+'Станд.норм.распр.'!H9*$B$12 -> 996.72837 | O16: =$E16*$B$11+$B$10+'Станд.норм.распр.'!I9*$B$12 -> 996.84761 | ... Q16: =$E16*$B$11+$B$10+'Станд.норм.распр.'!K9*$B$12 -> 995.59214
C17: X8 | D17: = | E17: 326 | G17: = | H17: =$E17*$B$11+$B$10+'Станд.норм.распр.'!B10*$B$12 -> 328.99866 | I17: =$E17*$B$11+$B$10+'Станд.норм.распр.'!C10*$B$12 -> 321.51248 | J17: =$E17*$B$11+$B$10+'Станд.норм.распр.'!D10*$B$12 -> 325.81846 | K17: =$E17*$B$11+$B$10+'Станд.норм.распр.'!E10*$B$12 -> 329.33698 | L17: =$E17*$B$11+$B$10+'Станд.норм.распр.'!F10*$B$12 -> 328.07356 | M17: =$E17*$B$11+$B$10+'Станд.норм.распр.'!G10*$B$12 -> 333.41787 | N17: =$E17*$B$11+$B$10+'Станд.норм.распр.'!H10*$B$12 -> 332.15591 | O17: =$E17*$B$11+$B$10+'Станд.норм.распр.'!I10*$B$12 -> 328.87336 | ... Q17: =$E17*$B$11+$B$10+'Станд.норм.распр.'!K10*$B$12 -> 324.62095
C18: X9 | D18: = | E18: 906 | G18: = | H18: =$E18*$B$11+$B$10+'Станд.норм.распр.'!B11*$B$12 -> 910.08695 | I18: =$E18*$B$11+$B$10+'Станд.норм.распр.'!C11*$B$12 -> 907.17394 | J18: =$E18*$B$11+$B$10+'Станд.норм.распр.'!D11*$B$12 -> 905.9815 | K18: =$E18*$B$11+$B$10+'Станд.норм.распр.'!E11*$B$12 -> 908.13189 | L18: =$E18*$B$11+$B$10+'Станд.норм.распр.'!F11*$B$12 -> 907.26297 | M18: =$E18*$B$11+$B$10+'Станд.норм.распр.'!G11*$B$12 -> 911.20759 | N18: =$E18*$B$11+$B$10+'Станд.норм.распр.'!H11*$B$12 -> 911.97541 | O18: =$E18*$B$11+$B$10+'Станд.норм.распр.'!I11*$B$12 -> 910.3927 | ... Q18: =$E18*$B$11+$B$10+'Станд.норм.распр.'!K11*$B$12 -> 909.0283
C19: X10 | D19: = | E19: 790 | G19: = | H19: =$E19*$B$11+$B$10+'Станд.норм.распр.'!B12*$B$12 -> 792.79655 | I19: =$E19*$B$11+$B$10+'Станд.норм.распр.'!C12*$B$12 -> 785.56386 | J19: =$E19*$B$11+$B$10+'Станд.норм.распр.'!D12*$B$12 -> 793.53099 | K19: =$E19*$B$11+$B$10+'Станд.норм.распр.'!E12*$B$12 -> 796.505 | L19: =$E19*$B$11+$B$10+'Станд.норм.распр.'!F12*$B$12 -> 793.71511 | M19: =$E19*$B$11+$B$10+'Станд.норм.распр.'!G12*$B$12 -> 794.78296 | N19: =$E19*$B$11+$B$10+'Станд.норм.распр.'!H12*$B$12 -> 799.76505 | O19: =$E19*$B$11+$B$10+'Станд.норм.распр.'!I12*$B$12 -> 795.58425 | ... Q19: =$E19*$B$11+$B$10+'Станд.норм.распр.'!K12*$B$12 -> 791.11897
C20: X11 | D20: = | E20: 127 | G20: = | H20: =$E20*$B$11+$B$10+'Станд.норм.распр.'!B13*$B$12 -> 128.29345 | I20: =$E20*$B$11+$B$10+'Станд.норм.распр.'!C13*$B$12 -> 126.16079 | J20: =$E20*$B$11+$B$10+'Станд.норм.распр.'!D13*$B$12 -> 128.8056 | K20: =$E20*$B$11+$B$10+'Станд.норм.распр.'!E13*$B$12 -> 127.24964 | L20: =$E20*$B$11+$B$10+'Станд.норм.распр.'!F13*$B$12 -> 130.65599 | M20: =$E20*$B$11+$B$10+'Станд.норм.распр.'!G13*$B$12 -> 126.44281 | N20: =$E20*$B$11+$B$10+'Станд.норм.распр.'!H13*$B$12 -> 129.63502 | O20: =$E20*$B$11+$B$10+'Станд.норм.распр.'!I13*$B$12 -> 136.31387 | ... Q20: =$E20*$B$11+$B$10+'Станд.норм.распр.'!K13*$B$12 -> 128.62391
C21: X12 | D21: = | E21: 685 | G21: = | H21: =$E21*$B$11+$B$10+'Станд.норм.распр.'!B14*$B$12 -> 686.09138 | I21: =$E21*$B$11+$B$10+'Станд.норм.распр.'!C14*$B$12 -> 684.97747 | J21: =$E21*$B$11+$B$10+'Станд.норм.распр.'!D14*$B$12 -> 687.01044 | K21: =$E21*$B$11+$B$10+'Станд.норм.распр.'!E14*$B$12 -> 687.81129 | L21: =$E21*$B$11+$B$10+'Станд.норм.распр.'!F14*$B$12 -> 688.53465 | M21: =$E21*$B$11+$B$10+'Станд.норм.распр.'!G14*$B$12 -> 683.87809 | N21: =$E21*$B$11+$B$10+'Станд.норм.распр.'!H14*$B$12 -> 688.36899 | O21: =$E21*$B$11+$B$10+'Станд.норм.распр.'!I14*$B$12 -> 684.89195 | ... Q21: =$E21*$B$11+$B$10+'Станд.норм.распр.'!K14*$B$12 -> 686.91014
C22: X13 | D22: = | E22: 320 | G22: = | H22: =$E22*$B$11+$B$10+'Станд.норм.распр.'!B15*$B$12 -> 322.43979 | I22: =$E22*$B$11+$B$10+'Станд.норм.распр.'!C15*$B$12 -> 327.85374 | J22: =$E22*$B$11+$B$10+'Станд.норм.распр.'!D15*$B$12 -> 323.73461 | K22: =$E22*$B$11+$B$10+'Станд.норм.распр.'!E15*$B$12 -> 322.64042 | L22: =$E22*$B$11+$B$10+'Станд.норм.распр.'!F15*$B$12 -> 316.90071 | M22: =$E22*$B$11+$B$10+'Станд.норм.распр.'!G15*$B$12 -> 326.09506 | N22: =$E22*$B$11+$B$10+'Станд.норм.распр.'!H15*$B$12 -> 320.87502 | O22: =$E22*$B$11+$B$10+'Станд.норм.распр.'!I15*$B$12 -> 327.41552 | ... Q22: =$E22*$B$11+$B$10+'Станд.норм.распр.'!K15*$B$12 -> 321.02459
C23: X14 | D23: = | E23: 658 | G23: = | H23: =$E23*$B$11+$B$10+'Станд.норм.распр.'!B16*$B$12 -> 660.01939 | I23: =$E23*$B$11+$B$10+'Станд.норм.распр.'!C16*$B$12 -> 661.02514 | J23: =$E23*$B$11+$B$10+'Станд.норм.распр.'!D16*$B$12 -> 659.96179 | K23: =$E23*$B$11+$B$10+'Станд.норм.распр.'!E16*$B$12 -> 656.27948 | L23: =$E23*$B$11+$B$10+'Станд.норм.распр.'!F16*$B$12 -> 665.33776 | M23: =$E23*$B$11+$B$10+'Станд.норм.распр.'!G16*$B$12 -> 661.86289 | N23: =$E23*$B$11+$B$10+'Станд.норм.распр.'!H16*$B$12 -> 660.19533 | O23: =$E23*$B$11+$B$10+'Станд.норм.распр.'!I16*$B$12 -> 658.50498 | ... Q23: =$E23*$B$11+$B$10+'Станд.норм.распр.'!K16*$B$12 -> 663.5791
C24: X15 | D24: = | E24: 436 | G24: = | H24: =$E24*$B$11+$B$10+'Станд.норм.распр.'!B17*$B$12 -> 437.36756 | I24: =$E24*$B$11+$B$10+'Станд.норм.распр.'!C17*$B$12 -> 438.25125 | J24: =$E24*$B$11+$B$10+'Станд.норм.распр.'!D17*$B$12 -> 437.32738 | K24: =$E24*$B$11+$B$10+'Станд.норм.распр.'!E17*$B$12 -> 439.34967 | L24: =$E24*$B$11+$B$10+'Станд.норм.распр.'!F17*$B$12 -> 434.95591 | M24: =$E24*$B$11+$B$10+'Станд.норм.распр.'!G17*$B$12 -> 438.06071 | N24: =$E24*$B$11+$B$10+'Станд.норм.распр.'!H17*$B$12 -> 438.25102 | O24: =$E24*$B$11+$B$10+'Станд.норм.распр.'!I17*$B$12 -> 437.7506 | ... Q24: =$E24*$B$11+$B$10+'Станд.норм.распр.'!K17*$B$12 -> 437.60007
... C109: X100 | D109: = | E109: 629 | G109: = | H109: =$E109*$B$11+$B$10+'Станд.норм.распр.'!B102*$B$12 -> 635.9827 | I109: =$E109*$B$11+$B$10+'Станд.норм.распр.'!C102*$B$12 -> 630.31359 | J109: =$E109*$B$11+$B$10+'Станд.норм.распр.'!D102*$B$12 -> 625.56449 | K109: =$E109*$B$11+$B$10+'Станд.норм.распр.'!E102*$B$12 -> 635.3614 | L109: =$E109*$B$11+$B$10+'Станд.норм.распр.'!F102*$B$12 -> 627.65321 | M109: =$E109*$B$11+$B$10+'Станд.норм.распр.'!G102*$B$12 -> 628.19677 | N109: =$E109*$B$11+$B$10+'Станд.норм.распр.'!H102*$B$12 -> 633.88524 | O109: =$E109*$B$11+$B$10+'Станд.норм.распр.'!I102*$B$12 -> 631.38079 | ... Q109: =$E109*$B$11+$B$10+'Станд.норм.распр.'!K102*$B$12 -> 631.96814

Sheet 2.
A1: Ui = ui * сигма + m | B1: m= | C1: 100
E2: 1 | H2: 2 | K2: 3 | N2: 4 | Q2: 5 | T2: 6 | W2: 7 | Z2: 8 | AC2: 9 | AF2: 10
E3: {=LINEST(H$10:H$109,$E$10:$E$109,1,1)} -> 1.0007359 | F3: 101.60851 | H3: {=LINEST(I$10:I$109,$E$10:$E$109,1,1)} -> 1.0001409 | I3: 101.92502 | K3: {=LINEST(J$10:J$109,$E$10:$E$109,1,1)} -> 0.99948982 | L3: 102.27142 | N3: {=LINEST(K$10:K$109,$E$10:$E$109,1,1)} -> 0.99856222 | O3: 102.76492 | Q3: {=LINEST(L$10:L$109,$E$10:$E$109,1,1)} -> 0.99958779 | R3: 102.2193 | T3: {=LINEST(M$10:M$109,$E$10:$E$109,1,1)} -> 0.99815911 | U3: 102.97937 | W3: {=LINEST(N$10:N$109,$E$10:$E$109,1,1)} -> 1.0003619 | X3: 101.80746 | Z3: {=LINEST(O$10:O$109,$E$10:$E$109,1,1)} -> 0.99990494 | AA3: 102.05057 | AC3: {=LINEST(P$10:P$109,$E$10:$E$109,1,1)} -> 1.0008826 | AD3: 101.53044 | AF3: {=LINEST(Q$10:Q$109,$E$10:$E$109,1,1)} -> 0.99966953 | AG3: 102.17581
E4: 0.00095820679 | F4: 0.57393678 | H4: 0.0011748164 | I4: 0.70367937 | K4: 0.0011386948 | L4: 0.68204364 | N4: 0.00096504595 | O4: 0.57803323 | Q4: 0.00094755799 | R4: 0.56755847 | T4: 0.0010215504 | U4: 0.61187768 | W4: 0.0011429048 | X4: 0.68456531 | Z4: 0.0011637727 | AA4: 0.69706452 | AC4: 0.00094139675 | AD4: 0.56386807 | AF4: 0.00093863998 | AG4: 0.56221685
E5: 0.99991016 | F5: 2.6368972 | H5: 0.9998648 | I5: 3.232987 | K5: 0.99987282 | L5: 3.1335837 | N5: 0.99990848 | O5: 2.6557179 | Q5: 0.99991194 | R5: 2.6075927 | T5: 0.99989736 | U5: 2.811213 | W5: 0.9998721 | X5: 3.1451693 | Z5: 0.99986726 | AA5: 3.2025957 | AC5: 0.99991331 | AD5: 2.5906375 | AF5: 0.99991361 | AG5: 2.5830511
E6: 1090738 | F6: 98 | H6: 724740.25 | I6: 98 | K6: 770445.72 | L6: 98 | N6: 1070666.6 | O6: 98 | Q6: 1112833.7 | R6: 98 | T6: 954728.63 | U6: 98 | W6: 766115.32 | X6: 98 | Z6: 738211.98 | AA6: 98 | AC6: 1130370.7 | AD6: 98 | AF6: 1134265.7 | AG6: 98
E7: 7584148.7 | F7: 681.41621 | H7: 7575133.7 | I7: 1024.3161 | K7: 7565273.8 | L7: 962.29601 | N7: 7551238 | O7: 691.17809 | Q7: 7566756.9 | R7: 666.35487 | T7: 7545142.5 | U7: 774.48601 | W7: 7578481.5 | X7: 969.4248 | Z7: 7571559.3 | AA7: 1005.1487 | AC7: 7586373 | AD7: 657.71745 | AF7: 7567994.6 | AG7: 653.87099
E8: =ABS(F3)/F4 -> 177.0378 | F8: =F7/(E7/F6) -> 0.0088050474 | H8: =ABS(I3)/I4 -> 144.84583 | I8: =I7/(H7/I6) -> 0.013251644 | K8: =ABS(L3)/L4 -> 149.9485 | L8: =L7/(K7/L6) -> 0.012465512 | N8: =ABS(O3)/O4 -> 177.78375 | O8: =O7/(N7/O6) -> 0.0089701123 | Q8: =ABS(R3)/R4 -> 180.10356 | R8: =R7/(Q7/R6) -> 0.00863022 | T8: =ABS(U3)/U4 -> 168.30059 | U8: =U7/(T7/U6) -> 0.010059403 | W8: =ABS(X3)/X4 -> 148.7184 | X8: =X7/(W7/X6) -> 0.012535972 | Z8: =ABS(AA3)/AA4 -> 146.40047 | AA8: =AA7/(Z7/AA6) -> 0.013009813 | AC8: =ABS(AD3)/AD4 -> 180.06063 | AD8: =AD7/(AC7/AD6) -> 0.0084963276 | AF8: =ABS(AG3)/AG4 -> 181.73737 | AG8: =AG7/(AF7/AG6) -> 0.0084671516
A9: Спецификация | B9: Y=а0+а1*X | H9: 1 | I9: 2 | J9: 3 | K9: 4 | L9: 5 | M9: 6 | N9: 7 | O9: 8 | P9: 9 | Q9: 10
A10: а0= | B10: 2 | C10: X1 | D10: = | E10: 212 | F10: Y1 | G10: = | H10: =$E10*$B$11+$B$10+'Станд.норм.распр.'!B3*$B$12+$C$1 -> 313.91565 | I10: =$E10*$B$11+$B$10+'Станд.норм.распр.'!C3*$B$12+$C$1 -> 308.89486 | J10: =$E10*$B$11+$B$10+'Станд.норм.распр.'!D3*$B$12+$C$1 -> 312.37545 | K10: =$E10*$B$11+$B$10+'Станд.норм.распр.'!E3*$B$12+$C$1 -> 315.19771 | L10: =$E10*$B$11+$B$10+'Станд.норм.распр.'!F3*$B$12+$C$1 -> 311.17976 | M10: =$E10*$B$11+$B$10+'Станд.норм.распр.'!G3*$B$12+$C$1 -> 315.14471 | N10: =$E10*$B$11+$B$10+'Станд.норм.распр.'!H3*$B$12+$C$1 -> 316.6478 | O10: =$E10*$B$11+$B$10+'Станд.норм.распр.'!I3*$B$12+$C$1 -> 307.63319 | ... Q10: =$E10*$B$11+$B$10+'Станд.норм.распр.'!K3*$B$12+$C$1 -> 311.16008
A11: а1= | B11: 1 | C11: X2 | D11: = | E11: 780 | G11: = | H11: =$E11*$B$11+$B$10+'Станд.норм.распр.'!B4*$B$12+$C$1 -> 881.59868 | I11: =$E11*$B$11+$B$10+'Станд.норм.распр.'!C4*$B$12+$C$1 -> 888.1771 | J11: =$E11*$B$11+$B$10+'Станд.норм.распр.'!D4*$B$12+$C$1 -> 888.13009 | K11: =$E11*$B$11+$B$10+'Станд.норм.распр.'!E4*$B$12+$C$1 -> 885.90956 | L11: =$E11*$B$11+$B$10+'Станд.норм.распр.'!F4*$B$12+$C$1 -> 884.35347 | M11: =$E11*$B$11+$B$10+'Станд.норм.распр.'!G4*$B$12+$C$1 -> 879.25319 | N11: =$E11*$B$11+$B$10+'Станд.норм.распр.'!H4*$B$12+$C$1 -> 879.42737 | O11: =$E11*$B$11+$B$10+'Станд.норм.распр.'!I4*$B$12+$C$1 -> 883.95477 | ... Q11: =$E11*$B$11+$B$10+'Станд.норм.распр.'!K4*$B$12+$C$1 -> 884.11069
A12: сигма= | B12: 3 | C12: X3 | D12: = | E12: 280 | G12: = | H12: =$E12*$B$11+$B$10+'Станд.норм.распр.'!B5*$B$12+$C$1 -> 380.08422 | I12: =$E12*$B$11+$B$10+'Станд.норм.распр.'!C5*$B$12+$C$1 -> 380.84417 | J12: =$E12*$B$11+$B$10+'Станд.норм.распр.'!D5*$B$12+$C$1 -> 384.8042 | K12: =$E12*$B$11+$B$10+'Станд.норм.распр.'!E5*$B$12+$C$1 -> 388.23759 | L12: =$E12*$B$11+$B$10+'Станд.норм.распр.'!F5*$B$12+$C$1 -> 383.12007 | M12: =$E12*$B$11+$B$10+'Станд.норм.распр.'!G5*$B$12+$C$1 -> 381.84537 | N12: =$E12*$B$11+$B$10+'Станд.норм.распр.'!H5*$B$12+$C$1 -> 385.89397 | O12: =$E12*$B$11+$B$10+'Станд.норм.распр.'!I5*$B$12+$C$1 -> 378.61965 | ... Q12: =$E12*$B$11+$B$10+'Станд.норм.распр.'!K5*$B$12+$C$1 -> 379.8946
C13: X4 | D13: = | E13: 888 | G13: = | H13: =$E13*$B$11+$B$10+'Станд.норм.распр.'!B6*$B$12+$C$1 -> 987.32089 | I13: =$E13*$B$11+$B$10+'Станд.норм.распр.'!C6*$B$12+$C$1 -> 996.43158 | J13: =$E13*$B$11+$B$10+'Станд.норм.распр.'!D6*$B$12+$C$1 -> 989.91657 | K13: =$E13*$B$11+$B$10+'Станд.норм.распр.'!E6*$B$12+$C$1 -> 989.08585 | L13: =$E13*$B$11+$B$10+'Станд.норм.распр.'!F6*$B$12+$C$1 -> 990.95897 | M13: =$E13*$B$11+$B$10+'Станд.норм.распр.'!G6*$B$12+$C$1 -> 990.87456 | N13: =$E13*$B$11+$B$10+'Станд.норм.распр.'!H6*$B$12+$C$1 -> 996.73723 | O13: =$E13*$B$11+$B$10+'Станд.норм.распр.'!I6*$B$12+$C$1 -> 990.93172 | ... Q13: =$E13*$B$11+$B$10+'Станд.норм.распр.'!K6*$B$12+$C$1 -> 990.13258
C14: X5 | D14: = | E14: 314 | G14: = | H14: =$E14*$B$11+$B$10+'Станд.норм.распр.'!B7*$B$12+$C$1 -> 416.01205 | I14: =$E14*$B$11+$B$10+'Станд.норм.распр.'!C7*$B$12+$C$1 -> 416.20774 | J14: =$E14*$B$11+$B$10+'Станд.норм.распр.'!D7*$B$12+$C$1 -> 417.38914 | K14: =$E14*$B$11+$B$10+'Станд.норм.распр.'!E7*$B$12+$C$1 -> 415.88924 | L14: =$E14*$B$11+$B$10+'Станд.норм.распр.'!F7*$B$12+$C$1 -> 416.63878 | M14: =$E14*$B$11+$B$10+'Станд.норм.распр.'!G7*$B$12+$C$1 -> 415.73562 | N14: =$E14*$B$11+$B$10+'Станд.норм.распр.'!H7*$B$12+$C$1 -> 415.20036 | O14: =$E14*$B$11+$B$10+'Станд.норм.распр.'!I7*$B$12+$C$1 -> 417.09967 | ... Q14: =$E14*$B$11+$B$10+'Станд.норм.распр.'!K7*$B$12+$C$1 -> 420.60455
C15: X6 | D15: = | E15: 780 | G15: = | H15: =$E15*$B$11+$B$10+'Станд.норм.распр.'!B8*$B$12+$C$1 -> 879.51662 | I15: =$E15*$B$11+$B$10+'Станд.норм.распр.'!C8*$B$12+$C$1 -> 876.53336 | J15: =$E15*$B$11+$B$10+'Станд.норм.распр.'!D8*$B$12+$C$1 -> 883.73651 | K15: =$E15*$B$11+$B$10+'Станд.норм.распр.'!E8*$B$12+$C$1 -> 879.17298 | L15: =$E15*$B$11+$B$10+'Станд.норм.распр.'!F8*$B$12+$C$1 -> 883.807 | M15: =$E15*$B$11+$B$10+'Станд.норм.распр.'!G8*$B$12+$C$1 -> 882.57296 | N15: =$E15*$B$11+$B$10+'Станд.норм.распр.'!H8*$B$12+$C$1 -> 881.37178 | O15: =$E15*$B$11+$B$10+'Станд.норм.распр.'!I8*$B$12+$C$1 -> 879.6092 | ... Q15: =$E15*$B$11+$B$10+'Станд.норм.распр.'!K8*$B$12+$C$1 -> 884.75136
C16: X7 | D16: = | E16: 993 | G16: = | H16: =$E16*$B$11+$B$10+'Станд.норм.распр.'!B9*$B$12+$C$1 -> 1098.8861 | I16: =$E16*$B$11+$B$10+'Станд.норм.распр.'!C9*$B$12+$C$1 -> 1092.2483 | J16: =$E16*$B$11+$B$10+'Станд.норм.распр.'!D9*$B$12+$C$1 -> 1097.7059 | K16: =$E16*$B$11+$B$10+'Станд.норм.распр.'!E9*$B$12+$C$1 -> 1098.4178 | L16: =$E16*$B$11+$B$10+'Станд.норм.распр.'!F9*$B$12+$C$1 -> 1095.7581 | M16: =$E16*$B$11+$B$10+'Станд.норм.распр.'!G9*$B$12+$C$1 -> 1094.7819 | N16: =$E16*$B$11+$B$10+'Станд.норм.распр.'!H9*$B$12+$C$1 -> 1096.7284 | O16: =$E16*$B$11+$B$10+'Станд.норм.распр.'!I9*$B$12+$C$1 -> 1096.8476 | ... Q16: =$E16*$B$11+$B$10+'Станд.норм.распр.'!K9*$B$12+$C$1 -> 1095.5921
C17: X8 | D17: = | E17: 326 | G17: = | H17: =$E17*$B$11+$B$10+'Станд.норм.распр.'!B10*$B$12+$C$1 -> 428.99866 | I17: =$E17*$B$11+$B$10+'Станд.норм.распр.'!C10*$B$12+$C$1 -> 421.51248 | J17: =$E17*$B$11+$B$10+'Станд.норм.распр.'!D10*$B$12+$C$1 -> 425.81846 | K17: =$E17*$B$11+$B$10+'Станд.норм.распр.'!E10*$B$12+$C$1 -> 429.33698 | L17: =$E17*$B$11+$B$10+'Станд.норм.распр.'!F10*$B$12+$C$1 -> 428.07356 | M17: =$E17*$B$11+$B$10+'Станд.норм.распр.'!G10*$B$12+$C$1 -> 433.41787 | N17: =$E17*$B$11+$B$10+'Станд.норм.распр.'!H10*$B$12+$C$1 -> 432.15591 | O17: =$E17*$B$11+$B$10+'Станд.норм.распр.'!I10*$B$12+$C$1 -> 428.87336 | ... Q17: =$E17*$B$11+$B$10+'Станд.норм.распр.'!K10*$B$12+$C$1 -> 424.62095
C18: X9 | D18: = | E18: 906 | G18: = | H18: =$E18*$B$11+$B$10+'Станд.норм.распр.'!B11*$B$12+$C$1 -> 1010.0869 | I18: =$E18*$B$11+$B$10+'Станд.норм.распр.'!C11*$B$12+$C$1 -> 1007.1739 | J18: =$E18*$B$11+$B$10+'Станд.норм.распр.'!D11*$B$12+$C$1 -> 1005.9815 | K18: =$E18*$B$11+$B$10+'Станд.норм.распр.'!E11*$B$12+$C$1 -> 1008.1319 | L18: =$E18*$B$11+$B$10+'Станд.норм.распр.'!F11*$B$12+$C$1 -> 1007.263 | M18: =$E18*$B$11+$B$10+'Станд.норм.распр.'!G11*$B$12+$C$1 -> 1011.2076 | N18: =$E18*$B$11+$B$10+'Станд.норм.распр.'!H11*$B$12+$C$1 -> 1011.9754 | O18: =$E18*$B$11+$B$10+'Станд.норм.распр.'!I11*$B$12+$C$1 -> 1010.3927 | ... Q18: =$E18*$B$11+$B$10+'Станд.норм.распр.'!K11*$B$12+$C$1 -> 1009.0283
C19: X10 | D19: = | E19: 790 | G19: = | H19: =$E19*$B$11+$B$10+'Станд.норм.распр.'!B12*$B$12+$C$1 -> 892.79655 | I19: =$E19*$B$11+$B$10+'Станд.норм.распр.'!C12*$B$12+$C$1 -> 885.56386 | J19: =$E19*$B$11+$B$10+'Станд.норм.распр.'!D12*$B$12+$C$1 -> 893.53099 | K19: =$E19*$B$11+$B$10+'Станд.норм.распр.'!E12*$B$12+$C$1 -> 896.505 | L19: =$E19*$B$11+$B$10+'Станд.норм.распр.'!F12*$B$12+$C$1 -> 893.71511 | M19: =$E19*$B$11+$B$10+'Станд.норм.распр.'!G12*$B$12+$C$1 -> 894.78296 | N19: =$E19*$B$11+$B$10+'Станд.норм.распр.'!H12*$B$12+$C$1 -> 899.76505 | O19: =$E19*$B$11+$B$10+'Станд.норм.распр.'!I12*$B$12+$C$1 -> 895.58425 | ... Q19: =$E19*$B$11+$B$10+'Станд.норм.распр.'!K12*$B$12+$C$1 -> 891.11897
C20: X11 | D20: = | E20: 127 | G20: = | H20: =$E20*$B$11+$B$10+'Станд.норм.распр.'!B13*$B$12+$C$1 -> 228.29345 | I20: =$E20*$B$11+$B$10+'Станд.норм.распр.'!C13*$B$12+$C$1 -> 226.16079 | J20: =$E20*$B$11+$B$10+'Станд.норм.распр.'!D13*$B$12+$C$1 -> 228.8056 | K20: =$E20*$B$11+$B$10+'Станд.норм.распр.'!E13*$B$12+$C$1 -> 227.24964 | L20: =$E20*$B$11+$B$10+'Станд.норм.распр.'!F13*$B$12+$C$1 -> 230.65599 | M20: =$E20*$B$11+$B$10+'Станд.норм.распр.'!G13*$B$12+$C$1 -> 226.44281 | N20: =$E20*$B$11+$B$10+'Станд.норм.распр.'!H13*$B$12+$C$1 -> 229.63502 | O20: =$E20*$B$11+$B$10+'Станд.норм.распр.'!I13*$B$12+$C$1 -> 236.31387 | ... Q20: =$E20*$B$11+$B$10+'Станд.норм.распр.'!K13*$B$12+$C$1 -> 228.62391
C21: X12 | D21: = | E21: 685 | G21: = | H21: =$E21*$B$11+$B$10+'Станд.норм.распр.'!B14*$B$12+$C$1 -> 786.09138 | I21: =$E21*$B$11+$B$10+'Станд.норм.распр.'!C14*$B$12+$C$1 -> 784.97747 | J21: =$E21*$B$11+$B$10+'Станд.норм.распр.'!D14*$B$12+$C$1 -> 787.01044 | K21: =$E21*$B$11+$B$10+'Станд.норм.распр.'!E14*$B$12+$C$1 -> 787.81129 | L21: =$E21*$B$11+$B$10+'Станд.норм.распр.'!F14*$B$12+$C$1 -> 788.53465 | M21: =$E21*$B$11+$B$10+'Станд.норм.распр.'!G14*$B$12+$C$1 -> 783.87809 | N21: =$E21*$B$11+$B$10+'Станд.норм.распр.'!H14*$B$12+$C$1 -> 788.36899 | O21: =$E21*$B$11+$B$10+'Станд.норм.распр.'!I14*$B$12+$C$1 -> 784.89195 | ... Q21: =$E21*$B$11+$B$10+'Станд.норм.распр.'!K14*$B$12+$C$1 -> 786.91014
C22: X13 | D22: = | E22: 320 | G22: = | H22: =$E22*$B$11+$B$10+'Станд.норм.распр.'!B15*$B$12+$C$1 -> 422.43979 | I22: =$E22*$B$11+$B$10+'Станд.норм.распр.'!C15*$B$12+$C$1 -> 427.85374 | J22: =$E22*$B$11+$B$10+'Станд.норм.распр.'!D15*$B$12+$C$1 -> 423.73461 | K22: =$E22*$B$11+$B$10+'Станд.норм.распр.'!E15*$B$12+$C$1 -> 422.64042 | L22: =$E22*$B$11+$B$10+'Станд.норм.распр.'!F15*$B$12+$C$1 -> 416.90071 | M22: =$E22*$B$11+$B$10+'Станд.норм.распр.'!G15*$B$12+$C$1 -> 426.09506 | N22: =$E22*$B$11+$B$10+'Станд.норм.распр.'!H15*$B$12+$C$1 -> 420.87502 | O22: =$E22*$B$11+$B$10+'Станд.норм.распр.'!I15*$B$12+$C$1 -> 427.41552 | ... Q22: =$E22*$B$11+$B$10+'Станд.норм.распр.'!K15*$B$12+$C$1 -> 421.02459
C23: X14 | D23: = | E23: 658 | G23: = | H23: =$E23*$B$11+$B$10+'Станд.норм.распр.'!B16*$B$12+$C$1 -> 760.01939 | I23: =$E23*$B$11+$B$10+'Станд.норм.распр.'!C16*$B$12+$C$1 -> 761.02514 | J23: =$E23*$B$11+$B$10+'Станд.норм.распр.'!D16*$B$12+$C$1 -> 759.96179 | K23: =$E23*$B$11+$B$10+'Станд.норм.распр.'!E16*$B$12+$C$1 -> 756.27948 | L23: =$E23*$B$11+$B$10+'Станд.норм.распр.'!F16*$B$12+$C$1 -> 765.33776 | M23: =$E23*$B$11+$B$10+'Станд.норм.распр.'!G16*$B$12+$C$1 -> 761.86289 | N23: =$E23*$B$11+$B$10+'Станд.норм.распр.'!H16*$B$12+$C$1 -> 760.19533 | O23: =$E23*$B$11+$B$10+'Станд.норм.распр.'!I16*$B$12+$C$1 -> 758.50498 | ... Q23: =$E23*$B$11+$B$10+'Станд.норм.распр.'!K16*$B$12+$C$1 -> 763.5791
C24: X15 | D24: = | E24: 436 | G24: = | H24: =$E24*$B$11+$B$10+'Станд.норм.распр.'!B17*$B$12+$C$1 -> 537.36756 | I24: =$E24*$B$11+$B$10+'Станд.норм.распр.'!C17*$B$12+$C$1 -> 538.25125 | J24: =$E24*$B$11+$B$10+'Станд.норм.распр.'!D17*$B$12+$C$1 -> 537.32738 | K24: =$E24*$B$11+$B$10+'Станд.норм.распр.'!E17*$B$12+$C$1 -> 539.34967 | L24: =$E24*$B$11+$B$10+'Станд.норм.распр.'!F17*$B$12+$C$1 -> 534.95591 | M24: =$E24*$B$11+$B$10+'Станд.норм.распр.'!G17*$B$12+$C$1 -> 538.06071 | N24: =$E24*$B$11+$B$10+'Станд.норм.распр.'!H17*$B$12+$C$1 -> 538.25102 | O24: =$E24*$B$11+$B$10+'Станд.норм.распр.'!I17*$B$12+$C$1 -> 537.7506 | ... Q24: =$E24*$B$11+$B$10+'Станд.норм.распр.'!K17*$B$12+$C$1 -> 537.60007
... C109: X100 | D109: = | E109: 629 | G109: = | H109: =$E109*$B$11+$B$10+'Станд.норм.распр.'!B102*$B$12+$C$1 -> 735.9827 | I109: =$E109*$B$11+$B$10+'Станд.норм.распр.'!C102*$B$12+$C$1 -> 730.31359 | J109: =$E109*$B$11+$B$10+'Станд.норм.распр.'!D102*$B$12+$C$1 -> 725.56449 | K109: =$E109*$B$11+$B$10+'Станд.норм.распр.'!E102*$B$12+$C$1 -> 735.3614 | L109: =$E109*$B$11+$B$10+'Станд.норм.распр.'!F102*$B$12+$C$1 -> 727.65321 | M109: =$E109*$B$11+$B$10+'Станд.норм.распр.'!G102*$B$12+$C$1 -> 728.19677 | N109: =$E109*$B$11+$B$10+'Станд.норм.распр.'!H102*$B$12+$C$1 -> 733.88524 | O109: =$E109*$B$11+$B$10+'Станд.норм.распр.'!I102*$B$12+$C$1 -> 731.38079 | ... Q109: =$E109*$B$11+$B$10+'Станд.норм.распр.'!K102*$B$12+$C$1 -> 731.96814

Sheet 3.
A1: Ui = ui * сигма * i | B1: i= | C1: 100
E2: 1 | H2: 2 | K2: 3 | N2: 4 | Q2: 5 | T2: 6 | W2: 7 | Z2: 8 | AC2: 9 | AF2: 10
E3: {=LINEST(H$10:H$109,$E$10:$E$109,1,1)} -> 1.0518885 | F3: -22.605987 | H3: {=LINEST(I$10:I$109,$E$10:$E$109,1,1)} -> 0.98695238 | I3: 12.736831 | K3: {=LINEST(J$10:J$109,$E$10:$E$109,1,1)} -> 0.95766422 | L3: 1.1443057 | N3: {=LINEST(K$10:K$109,$E$10:$E$109,1,1)} -> 0.90730983 | O3: 40.679836 | Q3: {=LINEST(L$10:L$109,$E$10:$E$109,1,1)} -> 0.95826368 | R3: 11.767664 | T3: {=LINEST(M$10:M$109,$E$10:$E$109,1,1)} -> 0.90390693 | U3: 43.539342 | W3: {=LINEST(N$10:N$109,$E$10:$E$109,1,1)} -> 1.0123311 | X3: -16.821722 | Z3: {=LINEST(O$10:O$109,$E$10:$E$109,1,1)} -> 0.94692751 | AA3: 31.715931 | AC3: {=LINEST(P$10:P$109,$E$10:$E$109,1,1)} -> 1.0660895 | AD3: -28.975468 | AF3: {=LINEST(Q$10:Q$109,$E$10:$E$109,1,1)} -> 0.94309473 | AG3: 30.450238
E4: 0.064953434 | F4: 38.905135 | H4: 0.069164686 | I4: 41.427547 | K4: 0.069392606 | L4: 41.564064 | N4: 0.056451596 | O4: 33.812792 | Q4: 0.051610419 | R4: 30.913074 | T4: 0.065199549 | U4: 39.052551 | W4: 0.058588629 | X4: 35.09281 | Z4: 0.06667032 | AA4: 39.933498 | AC4: 0.064445371 | AD4: 38.600821 | AF4: 0.048910361 | AG4: 29.295821
A5: Оценки не состоятельны!!!! | E5: 0.72797566 | F5: 178.74589 | H5: 0.67508945 | I5: 190.33487 | K5: 0.66026297 | L5: 190.96209 | N5: 0.72496667 | O5: 155.34961 | Q5: 0.77865256 | R5: 142.02714 | T5: 0.66230436 | U5: 179.42318 | W5: 0.7528691 | X5: 161.23053 | Z5: 0.673038 | AA5: 183.4706 | AC5: 0.7363148 | AD5: 177.34775 | AF5: 0.79140041 | AG5: 134.59683
E6: 262.26187 | F6: 98 | H6: 203.62148 | I6: 98 | K6: 190.4584 | L6: 98 | N6: 258.32045 | O6: 98 | Q6: 344.74287 | R6: 98 | T6: 192.20215 | U6: 98 | W6: 298.55097 | X6: 98 | Z6: 201.72902 | AA6: 98 | AC6: 273.6553 | AD6: 98 | AF6: 371.79959 | AG6: 98
E7: 8379291.4 | F7: 3131109.1 | H7: 7376669 | I7: 3550281.5 | K7: 6945354.6 | L7: 3573718.8 | N7: 6234177.1 | O7: 2365083.2 | Q7: 6954052.4 | R7: 1976827.4 | T7: 6187501.6 | U7: 3154882.3 | W7: 7760917.4 | X7: 2547537.8 | Z7: 6790493.9 | AA7: 3298823.3 | AC7: 8607067.5 | AD7: 3082317.9 | AF7: 6735634.8 | AG7: 1775397.9
E8: =ABS(F3)/F4 -> 0.58105408 | F8: =F7/(E7/F6) -> 36.619886 | H8: =ABS(I3)/I4 -> 0.30744836 | I8: =I7/(H7/I6) -> 47.165948 | K8: =ABS(L3)/L4 -> 0.02753113 | L8: =L7/(K7/L6) -> 50.42571 | N8: =ABS(O3)/O4 -> 1.2030901 | O8: =O7/(N7/O6) -> 37.178629 | Q8: =ABS(R3)/R4 -> 0.38066949 | R8: =R7/(Q7/R6) -> 27.858444 | T8: =ABS(U3)/U4 -> 1.1148911 | U8: =U7/(T7/U6) -> 49.968224 | W8: =ABS(X3)/X4 -> 0.47934954 | X8: =X7/(W7/X6) -> 32.168711 | Z8: =ABS(AA3)/AA4 -> 0.79421873 | AA8: =AA7/(Z7/AA6) -> 47.608419 | AC8: =ABS(AD3)/AD4 -> 0.75064384 | AD8: =AD7/(AC7/AD6) -> 35.095246 | AF8: =ABS(AG3)/AG4 -> 1.0394055 | AG8: =AG7/(AF7/AG6) -> 25.831121
A9: Спецификация | B9: Y=а0+а1*X | H9: 1 | I9: 2 | J9: 3 | K9: 4 | L9: 5 | M9: 6 | N9: 7 | O9: 8 | P9: 9 | Q9: 10
A10: а0= | B10: 2 | C10: X1 | D10: = | E10: 212 | F10: Y1 | G10: = | H10: =$E10*$B$11+$B$10+'Станд.норм.распр.'!B3*$B$12*$R10 -> 213.91565 | I10: =$E10*$B$11+$B$10+'Станд.норм.распр.'!C3*$B$12*$R10 -> 208.89486 | J10: =$E10*$B$11+$B$10+'Станд.норм.распр.'!D3*$B$12*$R10 -> 212.37545 | K10: =$E10*$B$11+$B$10+'Станд.норм.распр.'!E3*$B$12*$R10 -> 215.19771 | L10: =$E10*$B$11+$B$10+'Станд.норм.распр.'!F3*$B$12*$R10 -> 211.17976 | M10: =$E10*$B$11+$B$10+'Станд.норм.распр.'!G3*$B$12*$R10 -> 215.14471 | N10: =$E10*$B$11+$B$10+'Станд.норм.распр.'!H3*$B$12*$R10 -> 216.6478 | O10: =$E10*$B$11+$B$10+'Станд.норм.распр.'!I3*$B$12*$R10 -> 207.63319 | ... Q10: =$E10*$B$11+$B$10+'Станд.норм.распр.'!K3*$B$12*$R10 -> 211.16008 | R10: 1
A11: а1= | B11: 1 | C11: X2 | D11: = | E11: 780 | G11: = | H11: =$E11*$B$11+$B$10+'Станд.норм.распр.'!B4*$B$12*$R11 -> 781.19736 | I11: =$E11*$B$11+$B$10+'Станд.норм.распр.'!C4*$B$12*$R11 -> 794.35419 | J11: =$E11*$B$11+$B$10+'Станд.норм.распр.'!D4*$B$12*$R11 -> 794.26017 | K11: =$E11*$B$11+$B$10+'Станд.норм.распр.'!E4*$B$12*$R11 -> 789.81913 | L11: =$E11*$B$11+$B$10+'Станд.норм.распр.'!F4*$B$12*$R11 -> 786.70694 | M11: =$E11*$B$11+$B$10+'Станд.норм.распр.'!G4*$B$12*$R11 -> 776.50637 | N11: =$E11*$B$11+$B$10+'Станд.норм.распр.'!H4*$B$12*$R11 -> 776.85474 | O11: =$E11*$B$11+$B$10+'Станд.норм.распр.'!I4*$B$12*$R11 -> 785.90955 | ... Q11: =$E11*$B$11+$B$10+'Станд.норм.распр.'!K4*$B$12*$R11 -> 786.22139 | R11: 2
A12: сигма= | B12: 3 | C12: X3 | D12: = | E12: 280 | G12: = | H12: =$E12*$B$11+$B$10+'Станд.норм.распр.'!B5*$B$12*$R12 -> 276.25266 | I12: =$E12*$B$11+$B$10+'Станд.норм.распр.'!C5*$B$12*$R12 -> 278.53252 | J12: =$E12*$B$11+$B$10+'Станд.норм.распр.'!D5*$B$12*$R12 -> 290.4126 | K12: =$E12*$B$11+$B$10+'Станд.норм.распр.'!E5*$B$12*$R12 -> 300.71276 | L12: =$E12*$B$11+$B$10+'Станд.норм.распр.'!F5*$B$12*$R12 -> 285.3602 | M12: =$E12*$B$11+$B$10+'Станд.норм.распр.'!G5*$B$12*$R12 -> 281.5361 | N12: =$E12*$B$11+$B$10+'Станд.норм.распр.'!H5*$B$12*$R12 -> 293.68192 | O12: =$E12*$B$11+$B$10+'Станд.норм.распр.'!I5*$B$12*$R12 -> 271.85896 | ... Q12: =$E12*$B$11+$B$10+'Станд.норм.распр.'!K5*$B$12*$R12 -> 275.68379 | R12: 3
C13: X4 | D13: = | E13: 888 | G13: = | H13: =$E13*$B$11+$B$10+'Станд.норм.распр.'!B6*$B$12*$R13 -> 879.28355 | I13: =$E13*$B$11+$B$10+'Станд.норм.распр.'!C6*$B$12*$R13 -> 915.72633 | J13: =$E13*$B$11+$B$10+'Станд.норм.распр.'!D6*$B$12*$R13 -> 889.66628 | K13: =$E13*$B$11+$B$10+'Станд.норм.распр.'!E6*$B$12*$R13 -> 886.34339 | L13: =$E13*$B$11+$B$10+'Станд.норм.распр.'!F6*$B$12*$R13 -> 893.83587 | M13: =$E13*$B$11+$B$10+'Станд.норм.распр.'!G6*$B$12*$R13 -> 893.49824 | N13: =$E13*$B$11+$B$10+'Станд.норм.распр.'!H6*$B$12*$R13 -> 916.94891 | O13: =$E13*$B$11+$B$10+'Станд.норм.распр.'!I6*$B$12*$R13 -> 893.72686 | ... Q13: =$E13*$B$11+$B$10+'Станд.норм.распр.'!K6*$B$12*$R13 -> 890.53031 | R13: 4
C14: X5 | D14: = | E14: 314 | G14: = | H14: =$E14*$B$11+$B$10+'Станд.норм.распр.'!B7*$B$12*$R14 -> 316.06023 | I14: =$E14*$B$11+$B$10+'Станд.норм.распр.'!C7*$B$12*$R14 -> 317.03872 | J14: =$E14*$B$11+$B$10+'Станд.норм.распр.'!D7*$B$12*$R14 -> 322.94571 | K14: =$E14*$B$11+$B$10+'Станд.норм.распр.'!E7*$B$12*$R14 -> 315.44622 | L14: =$E14*$B$11+$B$10+'Станд.норм.распр.'!F7*$B$12*$R14 -> 319.19388 | M14: =$E14*$B$11+$B$10+'Станд.норм.распр.'!G7*$B$12*$R14 -> 314.67812 | N14: =$E14*$B$11+$B$10+'Станд.норм.распр.'!H7*$B$12*$R14 -> 312.00182 | O14: =$E14*$B$11+$B$10+'Станд.норм.распр.'!I7*$B$12*$R14 -> 321.49834 | ... Q14: =$E14*$B$11+$B$10+'Станд.норм.распр.'!K7*$B$12*$R14 -> 339.02274 | R14: 5
C15: X6 | D15: = | E15: 780 | G15: = | H15: =$E15*$B$11+$B$10+'Станд.норм.распр.'!B8*$B$12*$R15 -> 767.09973 | I15: =$E15*$B$11+$B$10+'Станд.норм.распр.'!C8*$B$12*$R15 -> 749.20016 | J15: =$E15*$B$11+$B$10+'Станд.норм.распр.'!D8*$B$12*$R15 -> 792.41904 | K15: =$E15*$B$11+$B$10+'Станд.норм.распр.'!E8*$B$12*$R15 -> 765.0379 | L15: =$E15*$B$11+$B$10+'Станд.норм.распр.'!F8*$B$12*$R15 -> 792.842 | M15: =$E15*$B$11+$B$10+'Станд.норм.распр.'!G8*$B$12*$R15 -> 785.43775 | N15: =$E15*$B$11+$B$10+'Станд.норм.распр.'!H8*$B$12*$R15 -> 778.2307 | O15: =$E15*$B$11+$B$10+'Станд.норм.распр.'!I8*$B$12*$R15 -> 767.6552 | ... Q15: =$E15*$B$11+$B$10+'Станд.норм.распр.'!K8*$B$12*$R15 -> 798.50813 | R15: 6
C16: X7 | D16: = | E16: 993 | G16: = | H16: =$E16*$B$11+$B$10+'Станд.норм.распр.'!B9*$B$12*$R16 -> 1022.2025 | I16: =$E16*$B$11+$B$10+'Станд.норм.распр.'!C9*$B$12*$R16 -> 975.73808 | J16: =$E16*$B$11+$B$10+'Станд.норм.распр.'!D9*$B$12*$R16 -> 1013.9412 | K16: =$E16*$B$11+$B$10+'Станд.норм.распр.'!E9*$B$12*$R16 -> 1018.9249 | L16: =$E16*$B$11+$B$10+'Станд.норм.распр.'!F9*$B$12*$R16 -> 1000.3067 | M16: =$E16*$B$11+$B$10+'Станд.норм.распр.'!G9*$B$12*$R16 -> 993.47331 | N16: =$E16*$B$11+$B$10+'Станд.норм.распр.'!H9*$B$12*$R16 -> 1007.0986 | O16: =$E16*$B$11+$B$10+'Станд.норм.распр.'!I9*$B$12*$R16 -> 1007.9333 | ... Q16: =$E16*$B$11+$B$10+'Станд.норм.распр.'!K9*$B$12*$R16 -> 999.14495 | R16: 7
C17: X8 | D17: = | E17: 326 | G17: = | H17: =$E17*$B$11+$B$10+'Станд.норм.распр.'!B10*$B$12*$R17 -> 335.9893 | I17: =$E17*$B$11+$B$10+'Станд.норм.распр.'!C10*$B$12*$R17 -> 276.09987 | J17: =$E17*$B$11+$B$10+'Станд.норм.распр.'!D10*$B$12*$R17 -> 310.54769 | K17: =$E17*$B$11+$B$10+'Станд.норм.распр.'!E10*$B$12*$R17 -> 338.69585 | L17: =$E17*$B$11+$B$10+'Станд.норм.распр.'!F10*$B$12*$R17 -> 328.58848 | M17: =$E17*$B$11+$B$10+'Станд.норм.распр.'!G10*$B$12*$R17 -> 371.34295 | N17: =$E17*$B$11+$B$10+'Станд.норм.распр.'!H10*$B$12*$R17 -> 361.24729 | O17: =$E17*$B$11+$B$10+'Станд.норм.распр.'!I10*$B$12*$R17 -> 334.98691 | ... Q17: =$E17*$B$11+$B$10+'Станд.норм.распр.'!K10*$B$12*$R17 -> 300.9676 | R17: 8
C18: X9 | D18: = | E18: 906 | G18: = | H18: =$E18*$B$11+$B$10+'Станд.норм.распр.'!B11*$B$12*$R18 -> 926.78254 | I18: =$E18*$B$11+$B$10+'Станд.норм.распр.'!C11*$B$12*$R18 -> 900.56544 | J18: =$E18*$B$11+$B$10+'Станд.норм.распр.'!D11*$B$12*$R18 -> 889.83348 | K18: =$E18*$B$11+$B$10+'Станд.норм.распр.'!E11*$B$12*$R18 -> 909.18699 | L18: =$E18*$B$11+$B$10+'Станд.норм.распр.'!F11*$B$12*$R18 -> 901.36674 | M18: =$E18*$B$11+$B$10+'Станд.норм.распр.'!G11*$B$12*$R18 -> 936.86827 | N18: =$E18*$B$11+$B$10+'Станд.норм.распр.'!H11*$B$12*$R18 -> 943.77873 | O18: =$E18*$B$11+$B$10+'Станд.норм.распр.'!I11*$B$12*$R18 -> 929.53427 | ... Q18: =$E18*$B$11+$B$10+'Станд.норм.распр.'!K11*$B$12*$R18 -> 917.25474 | R18: 9
C19: X10 | D19: = | E19: 790 | G19: = | H19: =$E19*$B$11+$B$10+'Станд.норм.распр.'!B12*$B$12*$R19 -> 799.96547 | I19: =$E19*$B$11+$B$10+'Станд.норм.распр.'!C12*$B$12*$R19 -> 727.63861 | J19: =$E19*$B$11+$B$10+'Станд.норм.распр.'!D12*$B$12*$R19 -> 807.30987 | K19: =$E19*$B$11+$B$10+'Станд.норм.распр.'!E12*$B$12*$R19 -> 837.05 | L19: =$E19*$B$11+$B$10+'Станд.норм.распр.'!F12*$B$12*$R19 -> 809.15111 | M19: =$E19*$B$11+$B$10+'Станд.норм.распр.'!G12*$B$12*$R19 -> 819.82958 | N19: =$E19*$B$11+$B$10+'Станд.норм.распр.'!H12*$B$12*$R19 -> 869.65047 | O19: =$E19*$B$11+$B$10+'Станд.норм.распр.'!I12*$B$12*$R19 -> 827.84246 | ... Q19: =$E19*$B$11+$B$10+'Станд.норм.распр.'!K12*$B$12*$R19 -> 783.18972 | R19: 10
C20: X11 | D20: = | E20: 127 | G20: = | H20: =$E20*$B$11+$B$10+'Станд.норм.распр.'!B13*$B$12*$R20 -> 121.2279 | I20: =$E20*$B$11+$B$10+'Станд.норм.распр.'!C13*$B$12*$R20 -> 97.768734 | J20: =$E20*$B$11+$B$10+'Станд.норм.распр.'!D13*$B$12*$R20 -> 126.86155 | K20: =$E20*$B$11+$B$10+'Станд.норм.распр.'!E13*$B$12*$R20 -> 109.746 | L20: =$E20*$B$11+$B$10+'Станд.норм.распр.'!F13*$B$12*$R20 -> 147.21591 | M20: =$E20*$B$11+$B$10+'Станд.норм.распр.'!G13*$B$12*$R20 -> 100.87091 | N20: =$E20*$B$11+$B$10+'Станд.норм.распр.'!H13*$B$12*$R20 -> 135.98523 | O20: =$E20*$B$11+$B$10+'Станд.норм.распр.'!I13*$B$12*$R20 -> 209.45252 | ... Q20: =$E20*$B$11+$B$10+'Станд.норм.распр.'!K13*$B$12*$R20 -> 124.86296 | R20: 11
C21: X12 | D21: = | E21: 685 | G21: = | H21: =$E21*$B$11+$B$10+'Станд.норм.распр.'!B14*$B$12*$R21 -> 676.09657 | I21: =$E21*$B$11+$B$10+'Станд.норм.распр.'!C14*$B$12*$R21 -> 662.72964 | J21: =$E21*$B$11+$B$10+'Станд.норм.распр.'!D14*$B$12*$R21 -> 687.12532 | K21: =$E21*$B$11+$B$10+'Станд.норм.распр.'!E14*$B$12*$R21 -> 696.73553 | L21: =$E21*$B$11+$B$10+'Станд.норм.распр.'!F14*$B$12*$R21 -> 705.41579 | M21: =$E21*$B$11+$B$10+'Станд.норм.распр.'!G14*$B$12*$R21 -> 649.53707 | N21: =$E21*$B$11+$B$10+'Станд.норм.распр.'!H14*$B$12*$R21 -> 703.42792 | O21: =$E21*$B$11+$B$10+'Станд.норм.распр.'!I14*$B$12*$R21 -> 661.70343 | ... Q21: =$E21*$B$11+$B$10+'Станд.норм.распр.'!K14*$B$12*$R21 -> 685.92165 | R21: 12
C22: X13 | D22: = | E22: 320 | G22: = | H22: =$E22*$B$11+$B$10+'Станд.норм.распр.'!B15*$B$12*$R22 -> 327.71728 | I22: =$E22*$B$11+$B$10+'Станд.норм.распр.'!C15*$B$12*$R22 -> 398.09868 | J22: =$E22*$B$11+$B$10+'Станд.норм.распр.'!D15*$B$12*$R22 -> 344.54988 | K22: =$E22*$B$11+$B$10+'Станд.норм.распр.'!E15*$B$12*$R22 -> 330.32545 | L22: =$E22*$B$11+$B$10+'Станд.норм.распр.'!F15*$B$12*$R22 -> 255.70921 | M22: =$E22*$B$11+$B$10+'Станд.норм.распр.'!G15*$B$12*$R22 -> 375.23577 | N22: =$E22*$B$11+$B$10+'Станд.норм.распр.'!H15*$B$12*$R22 -> 307.3753 | O22: =$E22*$B$11+$B$10+'Станд.норм.распр.'!I15*$B$12*$R22 -> 392.40179 | ... Q22: =$E22*$B$11+$B$10+'Станд.норм.распр.'!K15*$B$12*$R22 -> 309.31972 | R22: 13
C23: X14 | D23: = | E23: 658 | G23: = | H23: =$E23*$B$11+$B$10+'Станд.норм.распр.'!B16*$B$12*$R23 -> 660.2715 | I23: =$E23*$B$11+$B$10+'Станд.норм.распр.'!C16*$B$12*$R23 -> 674.352 | J23: =$E23*$B$11+$B$10+'Станд.норм.распр.'!D16*$B$12*$R23 -> 659.46503 | K23: =$E23*$B$11+$B$10+'Станд.норм.распр.'!E16*$B$12*$R23 -> 607.91272 | L23: =$E23*$B$11+$B$10+'Станд.норм.распр.'!F16*$B$12*$R23 -> 734.72865 | M23: =$E23*$B$11+$B$10+'Станд.норм.распр.'!G16*$B$12*$R23 -> 686.0805 | N23: =$E23*$B$11+$B$10+'Станд.норм.распр.'!H16*$B$12*$R23 -> 662.73455 | O23: =$E23*$B$11+$B$10+'Станд.норм.распр.'!I16*$B$12*$R23 -> 639.0697 | ... Q23: =$E23*$B$11+$B$10+'Станд.норм.распр.'!K16*$B$12*$R23 -> 710.10744 | R23: 14
C24: X15 | D24: = | E24: 436 | G24: = | H24: =$E24*$B$11+$B$10+'Станд.норм.распр.'!B17*$B$12*$R24 -> 428.51342 | I24: =$E24*$B$11+$B$10+'Станд.норм.распр.'!C17*$B$12*$R24 -> 441.76868 | J24: =$E24*$B$11+$B$10+'Станд.норм.распр.'!D17*$B$12*$R24 -> 427.91066 | K24: =$E24*$B$11+$B$10+'Станд.норм.распр.'!E17*$B$12*$R24 -> 458.24498 | L24: =$E24*$B$11+$B$10+'Станд.норм.распр.'!F17*$B$12*$R24 -> 392.33868 | M24: =$E24*$B$11+$B$10+'Станд.норм.распр.'!G17*$B$12*$R24 -> 438.91058 | N24: =$E24*$B$11+$B$10+'Станд.норм.распр.'!H17*$B$12*$R24 -> 441.76526 | O24: =$E24*$B$11+$B$10+'Станд.норм.распр.'!I17*$B$12*$R24 -> 434.25894 | ... Q24: =$E24*$B$11+$B$10+'Станд.норм.распр.'!K17*$B$12*$R24 -> 432.00102 | R24: 15
... C109: X100 | D109: = | E109: 629 | G109: = | H109: =$E109*$B$11+$B$10+'Станд.норм.распр.'!B102*$B$12*$R109 -> 1129.27 | I109: =$E109*$B$11+$B$10+'Станд.норм.распр.'!C102*$B$12*$R109 -> 562.35918 | J109: =$E109*$B$11+$B$10+'Станд.норм.распр.'!D102*$B$12*$R109 -> 87.449306 | K109: =$E109*$B$11+$B$10+'Станд.норм.распр.'!E102*$B$12*$R109 -> 1067.1395 | L109: =$E109*$B$11+$B$10+'Станд.норм.распр.'!F102*$B$12*$R109 -> 296.32063 | M109: =$E109*$B$11+$B$10+'Станд.норм.распр.'!G102*$B$12*$R109 -> 350.67653 | N109: =$E109*$B$11+$B$10+'Станд.норм.распр.'!H102*$B$12*$R109 -> 919.52426 | O109: =$E109*$B$11+$B$10+'Станд.норм.распр.'!I102*$B$12*$R109 -> 669.0793 | ... Q109: =$E109*$B$11+$B$10+'Станд.норм.распр.'!K102*$B$12*$R109 -> 727.81414 | R109: 100

Sheet 4.
A1: Ui = ui * сигма | B1: при i=1 | D1: Ui = d * Ui-1 + c * ui | E1: при i=2, 3, …
A2: d= | B2: 0.2 | E2: 1 | H2: 2 | K2: 3 | N2: 4 | Q2: 5 | T2: 6 | W2: 7 | Z2: 8 | AC2: 9 | AF2: 10
E3: {=LINEST(H$10:H$109,$E$10:$E$109,1,1)} -> 1.0006672 | F3: 1.6417061 | H3: {=LINEST(I$10:I$109,$E$10:$E$109,1,1)} -> 1.0000347 | I3: 1.9819772 | K3: {=LINEST(J$10:J$109,$E$10:$E$109,1,1)} -> 0.99940707 | L3: 2.3190676 | N3: {=LINEST(K$10:K$109,$E$10:$E$109,1,1)} -> 0.99859239 | O3: 2.7459562 | Q3: {=LINEST(L$10:L$109,$E$10:$E$109,1,1)} -> 0.99967842 | R3: 2.1733153 | T3: {=LINEST(M$10:M$109,$E$10:$E$109,1,1)} -> 0.99814847 | U3: 2.9869037 | W3: {=LINEST(N$10:N$109,$E$10:$E$109,1,1)} -> 1.0004251 | X3: 1.7718933 | Z3: {=LINEST(O$10:O$109,$E$10:$E$109,1,1)} -> 0.99979625 | AA3: 2.1081442 | AC3: {=LINEST(P$10:P$109,$E$10:$E$109,1,1)} -> 1.0009576 | AD3: 1.4939863 | AF3: {=LINEST(Q$10:Q$109,$E$10:$E$109,1,1)} -> 0.99980015 | AG3: 2.1056756
E4: 0.00096669277 | F4: 0.57901962 | H4: 0.001176467 | I4: 0.70466803 | K4: 0.0011417667 | L4: 0.68388356 | N4: 0.0009553016 | O4: 0.57219666 | Q4: 0.00094803819 | R4: 0.56784609 | T4: 0.0010313693 | U4: 0.61775889 | W4: 0.0011350878 | X4: 0.67988316 | Z4: 0.0011654919 | AA4: 0.69809428 | AC4: 0.00094337899 | AD4: 0.56505538 | AF4: 0.00093675843 | AG4: 0.56108986
E5: 0.99990855 | F5: 2.6602498 | H5: 0.99986439 | I5: 3.2375293 | K5: 0.99987211 | L5: 3.1420371 | N5: 0.99991032 | O5: 2.6289024 | Q5: 0.99991187 | R5: 2.6089141 | T5: 0.99989538 | U5: 2.8382336 | W5: 0.99987386 | X5: 3.1236576 | Z5: 0.99986684 | AA5: 3.2073268 | AC5: 0.99991296 | AD5: 2.5960924 | AF5: 0.99991398 | AG5: 2.5778733
E6: 1071525.3 | F6: 98 | H6: 722554.58 | I6: 98 | K6: 766178.79 | L6: 98 | N6: 1092686.3 | O6: 98 | Q6: 1111908.3 | R6: 98 | T6: 936616.71 | U6: 98 | W6: 776801.85 | X6: 98 | Z6: 735875.71 | AA6: 98 | AC6: 1125794.1 | AD6: 98 | AF6: 1139124.5 | AG6: 98
E7: 7583108.2 | F7: 693.53905 | H7: 7573525.1 | I7: 1027.1964 | K7: 7564021.2 | L7: 967.4949 | N7: 7551694.3 | O7: 677.2905 | Q7: 7568129.1 | R7: 667.03041 | T7: 7544981.6 | U7: 789.44587 | W7: 7579439.7 | X7: 956.20921 | Z7: 7569913.3 | AA7: 1008.1207 | AC7: 7587509.9 | AD7: 660.4902 | AF7: 7569972.4 | AG7: 651.25219
E8: =ABS(F3)/F4 -> 2.8353204 | F8: =F7/(E7/F6) -> 0.0089629246 | H8: =ABS(I3)/I4 -> 2.8126396 | I8: =I7/(H7/I6) -> 0.013291729 | K8: =ABS(L3)/L4 -> 3.391027 | L8: =L7/(K7/L6) -> 0.012534933 | N8: =ABS(O3)/O4 -> 4.7989729 | O8: =O7/(N7/O6) -> 0.008789348 | Q8: =ABS(R3)/R4 -> 3.8272964 | R8: =R7/(Q7/R6) -> 0.0086374029 | T8: =ABS(U3)/U4 -> 4.8350639 | U8: =U7/(T7/U6) -> 0.010253928 | W8: =ABS(X3)/X4 -> 2.6061733 | X8: =X7/(W7/X6) -> 0.012363513 | Z8: =ABS(AA3)/AA4 -> 3.019856 | AA8: =AA7/(Z7/AA6) -> 0.013051117 | AC8: =ABS(AD3)/AD4 -> 2.6439644 | AD8: =AD7/(AC7/AD6) -> 0.0085308672 | AF8: =ABS(AG3)/AG4 -> 3.7528313 | AG8: =AG7/(AF7/AG6) -> 0.0084310366
A9: Спецификация | B9: Y=а0+а1*X | H9: 1 | I9: 2 | J9: 3 | K9: 4 | L9: 5 | M9: 6 | N9: 7 | O9: 8 | P9: 9 | Q9: 10
A10: а0= | B10: 2 | C10: X1 | D10: = | E10: 212 | F10: Y1 | G10: = | H10: =$E10*$B$11+$B$10+'Станд.норм.распр.'!B3*$B$12 -> 213.91565 | I10: =$E10*$B$11+$B$10+'Станд.норм.распр.'!C3*$B$12 -> 208.89486 | J10: =$E10*$B$11+$B$10+'Станд.норм.распр.'!D3*$B$12 -> 212.37545 | K10: =$E10*$B$11+$B$10+'Станд.норм.распр.'!E3*$B$12 -> 215.19771 | L10: =$E10*$B$11+$B$10+'Станд.норм.распр.'!F3*$B$12 -> 211.17976 | M10: =$E10*$B$11+$B$10+'Станд.норм.распр.'!G3*$B$12 -> 215.14471 | N10: =$E10*$B$11+$B$10+'Станд.норм.распр.'!H3*$B$12 -> 216.6478 | O10: =$E10*$B$11+$B$10+'Станд.норм.распр.'!I3*$B$12 -> 207.63319 | ... Q10: =$E10*$B$11+$B$10+'Станд.норм.распр.'!K3*$B$12 -> 211.16008
A11: а1= | B11: 1 | C11: X2 | D11: = | E11: 780 | G11: = | H11: =$E11*$B$11+$B$10+'Станд.норм.распр.'!B4*$B$12+$B$2*'Станд.норм.распр.'!B3 -> 781.59306 | I11: =$E11*$B$11+$B$10+'Станд.норм.распр.'!C4*$B$12+$B$2*'Станд.норм.распр.'!C3 -> 787.83675 | J11: =$E11*$B$11+$B$10+'Станд.норм.распр.'!D4*$B$12+$B$2*'Станд.норм.распр.'!D3 -> 788.02178 | K11: =$E11*$B$11+$B$10+'Станд.норм.распр.'!E4*$B$12+$B$2*'Станд.норм.распр.'!E3 -> 785.98941 | L11: =$E11*$B$11+$B$10+'Станд.норм.распр.'!F4*$B$12+$B$2*'Станд.норм.распр.'!F3 -> 784.16545 | M11: =$E11*$B$11+$B$10+'Станд.норм.распр.'!G4*$B$12+$B$2*'Станд.норм.распр.'!G3 -> 779.3295 | N11: =$E11*$B$11+$B$10+'Станд.норм.распр.'!H4*$B$12+$B$2*'Станд.норм.распр.'!H3 -> 779.60389 | O11: =$E11*$B$11+$B$10+'Станд.норм.распр.'!I4*$B$12+$B$2*'Станд.норм.распр.'!I3 -> 783.53032 | ... Q11: =$E11*$B$11+$B$10+'Станд.норм.распр.'!K4*$B$12+$B$2*'Станд.норм.распр.'!K3 -> 783.92137
A12: сигма= | B12: 3 | C12: X3 | D12: = | E12: 280 | G12: = | H12: =$E12*$B$11+$B$10+'Станд.норм.распр.'!B5*$B$12+$B$2*'Станд.норм.распр.'!B4 -> 280.05746 | I12: =$E12*$B$11+$B$10+'Станд.норм.распр.'!C5*$B$12+$B$2*'Станд.норм.распр.'!C4 -> 281.25598 | J12: =$E12*$B$11+$B$10+'Станд.норм.распр.'!D5*$B$12+$B$2*'Станд.норм.распр.'!D4 -> 285.21287 | K12: =$E12*$B$11+$B$10+'Станд.норм.распр.'!E5*$B$12+$B$2*'Станд.норм.распр.'!E4 -> 288.49823 | L12: =$E12*$B$11+$B$10+'Станд.норм.распр.'!F5*$B$12+$B$2*'Станд.норм.распр.'!F4 -> 283.27696 | M12: =$E12*$B$11+$B$10+'Станд.норм.распр.'!G5*$B$12+$B$2*'Станд.норм.распр.'!G4 -> 281.66225 | N12: =$E12*$B$11+$B$10+'Станд.норм.распр.'!H5*$B$12+$B$2*'Станд.норм.распр.'!H4 -> 285.72247 | O12: =$E12*$B$11+$B$10+'Станд.норм.распр.'!I5*$B$12+$B$2*'Станд.норм.распр.'!I4 -> 278.74997 | ... Q12: =$E12*$B$11+$B$10+'Станд.норм.распр.'!K5*$B$12+$B$2*'Станд.норм.распр.'!K4 -> 280.03531
C13: X4 | D13: = | E13: 888 | G13: = | H13: =$E13*$B$11+$B$10+'Станд.норм.распр.'!B6*$B$12+$B$2*'Станд.норм.распр.'!B5 -> 887.19317 | I13: =$E13*$B$11+$B$10+'Станд.норм.распр.'!C6*$B$12+$B$2*'Станд.норм.распр.'!C5 -> 896.35453 | J13: =$E13*$B$11+$B$10+'Станд.норм.распр.'!D6*$B$12+$B$2*'Станд.норм.распр.'!D5 -> 890.10352 | K13: =$E13*$B$11+$B$10+'Станд.норм.распр.'!E6*$B$12+$B$2*'Станд.норм.распр.'!E5 -> 889.50169 | L13: =$E13*$B$11+$B$10+'Станд.норм.распр.'!F6*$B$12+$B$2*'Станд.норм.распр.'!F5 -> 891.03364 | M13: =$E13*$B$11+$B$10+'Станд.норм.распр.'!G6*$B$12+$B$2*'Станд.норм.распр.'!G5 -> 890.86425 | N13: =$E13*$B$11+$B$10+'Станд.норм.распр.'!H6*$B$12+$B$2*'Станд.норм.распр.'!H5 -> 896.99683 | O13: =$E13*$B$11+$B$10+'Станд.норм.распр.'!I6*$B$12+$B$2*'Станд.норм.распр.'!I5 -> 890.70636 | ... Q13: =$E13*$B$11+$B$10+'Станд.норм.распр.'!K6*$B$12+$B$2*'Станд.норм.распр.'!K5 -> 889.99222
C14: X5 | D14: = | E14: 314 | G14: = | H14: =$E14*$B$11+$B$10+'Станд.норм.распр.'!B7*$B$12+$B$2*'Станд.норм.распр.'!B6 -> 315.83344 | I14: =$E14*$B$11+$B$10+'Станд.норм.распр.'!C7*$B$12+$B$2*'Станд.норм.распр.'!C6 -> 316.63652 | J14: =$E14*$B$11+$B$10+'Станд.норм.распр.'!D7*$B$12+$B$2*'Станд.норм.распр.'!D6 -> 317.38358 | K14: =$E14*$B$11+$B$10+'Станд.норм.распр.'!E7*$B$12+$B$2*'Станд.норм.распр.'!E6 -> 315.8283 | L14: =$E14*$B$11+$B$10+'Станд.норм.распр.'!F7*$B$12+$B$2*'Станд.норм.распр.'!F6 -> 316.70271 | M14: =$E14*$B$11+$B$10+'Станд.норм.распр.'!G7*$B$12+$B$2*'Станд.норм.распр.'!G6 -> 315.79393 | N14: =$E14*$B$11+$B$10+'Станд.норм.распр.'!H7*$B$12+$B$2*'Станд.норм.распр.'!H6 -> 315.64951 | O14: =$E14*$B$11+$B$10+'Станд.норм.распр.'!I7*$B$12+$B$2*'Станд.норм.распр.'!I6 -> 317.16178 | ... Q14: =$E14*$B$11+$B$10+'Станд.норм.распр.'!K7*$B$12+$B$2*'Станд.норм.распр.'!K6 -> 320.61339
C15: X6 | D15: = | E15: 780 | G15: = | H15: =$E15*$B$11+$B$10+'Станд.норм.распр.'!B8*$B$12+$B$2*'Станд.норм.распр.'!B7 -> 779.51743 | I15: =$E15*$B$11+$B$10+'Станд.норм.распр.'!C8*$B$12+$B$2*'Станд.норм.распр.'!C7 -> 776.54721 | J15: =$E15*$B$11+$B$10+'Станд.норм.распр.'!D8*$B$12+$B$2*'Станд.норм.распр.'!D7 -> 783.82912 | K15: =$E15*$B$11+$B$10+'Станд.норм.распр.'!E8*$B$12+$B$2*'Станд.норм.распр.'!E7 -> 779.1656 | L15: =$E15*$B$11+$B$10+'Станд.норм.распр.'!F8*$B$12+$B$2*'Станд.норм.распр.'!F7 -> 783.84959 | M15: =$E15*$B$11+$B$10+'Станд.норм.распр.'!G8*$B$12+$B$2*'Станд.норм.распр.'!G7 -> 782.55533 | N15: =$E15*$B$11+$B$10+'Станд.норм.распр.'!H8*$B$12+$B$2*'Станд.норм.распр.'!H7 -> 781.31847 | O15: =$E15*$B$11+$B$10+'Станд.норм.распр.'!I8*$B$12+$B$2*'Станд.норм.распр.'!I7 -> 779.68251 | ... Q15: =$E15*$B$11+$B$10+'Станд.норм.распр.'!K8*$B$12+$B$2*'Станд.норм.распр.'!K7 -> 785.05833
C16: X7 | D16: = | E16: 993 | G16: = | H16: =$E16*$B$11+$B$10+'Станд.норм.распр.'!B9*$B$12+$B$2*'Станд.норм.распр.'!B8 -> 998.72052 | I16: =$E16*$B$11+$B$10+'Станд.норм.распр.'!C9*$B$12+$B$2*'Станд.норм.распр.'!C8 -> 991.88385 | J16: =$E16*$B$11+$B$10+'Станд.норм.распр.'!D9*$B$12+$B$2*'Станд.норм.распр.'!D8 -> 997.82165 | K16: =$E16*$B$11+$B$10+'Станд.норм.распр.'!E9*$B$12+$B$2*'Станд.норм.распр.'!E8 -> 998.22938 | L16: =$E16*$B$11+$B$10+'Станд.норм.распр.'!F9*$B$12+$B$2*'Станд.норм.распр.'!F8 -> 995.87857 | M16: =$E16*$B$11+$B$10+'Станд.норм.распр.'!G9*$B$12+$B$2*'Станд.норм.распр.'!G8 -> 994.8201 | N16: =$E16*$B$11+$B$10+'Станд.норм.распр.'!H9*$B$12+$B$2*'Станд.норм.распр.'!H8 -> 996.68649 | O16: =$E16*$B$11+$B$10+'Станд.норм.распр.'!I9*$B$12+$B$2*'Станд.норм.распр.'!I8 -> 996.68822 | ... Q16: =$E16*$B$11+$B$10+'Станд.норм.распр.'!K9*$B$12+$B$2*'Станд.норм.распр.'!K8 -> 995.77556
C17: X8 | D17: = | E17: 326 | G17: = | H17: =$E17*$B$11+$B$10+'Станд.норм.распр.'!B10*$B$12+$B$2*'Станд.норм.распр.'!B9 -> 329.25773 | I17: =$E17*$B$11+$B$10+'Станд.норм.распр.'!C10*$B$12+$B$2*'Станд.норм.распр.'!C9 -> 321.32904 | J17: =$E17*$B$11+$B$10+'Станд.норм.распр.'!D10*$B$12+$B$2*'Станд.норм.распр.'!D9 -> 325.99885 | K17: =$E17*$B$11+$B$10+'Станд.норм.распр.'!E10*$B$12+$B$2*'Станд.норм.распр.'!E9 -> 329.56484 | L17: =$E17*$B$11+$B$10+'Станд.норм.распр.'!F10*$B$12+$B$2*'Станд.норм.распр.'!F9 -> 328.1241 | M17: =$E17*$B$11+$B$10+'Станд.норм.распр.'!G10*$B$12+$B$2*'Станд.норм.распр.'!G9 -> 333.40333 | N17: =$E17*$B$11+$B$10+'Станд.норм.распр.'!H10*$B$12+$B$2*'Станд.норм.распр.'!H9 -> 332.27114 | O17: =$E17*$B$11+$B$10+'Станд.норм.распр.'!I10*$B$12+$B$2*'Станд.норм.распр.'!I9 -> 328.99654 | ... Q17: =$E17*$B$11+$B$10+'Станд.норм.распр.'!K10*$B$12+$B$2*'Станд.норм.распр.'!K9 -> 324.66043
C18: X9 | D18: = | E18: 906 | G18: = | H18: =$E18*$B$11+$B$10+'Станд.норм.распр.'!B11*$B$12+$B$2*'Станд.норм.распр.'!B10 -> 910.15353 | I18: =$E18*$B$11+$B$10+'Станд.норм.распр.'!C11*$B$12+$B$2*'Станд.норм.распр.'!C10 -> 906.74144 | J18: =$E18*$B$11+$B$10+'Станд.норм.распр.'!D11*$B$12+$B$2*'Станд.норм.распр.'!D10 -> 905.83606 | K18: =$E18*$B$11+$B$10+'Станд.норм.распр.'!E11*$B$12+$B$2*'Станд.норм.распр.'!E10 -> 908.22102 | L18: =$E18*$B$11+$B$10+'Станд.норм.распр.'!F11*$B$12+$B$2*'Станд.норм.распр.'!F10 -> 907.26788 | M18: =$E18*$B$11+$B$10+'Станд.норм.распр.'!G11*$B$12+$B$2*'Станд.норм.распр.'!G10 -> 911.56878 | N18: =$E18*$B$11+$B$10+'Станд.норм.распр.'!H11*$B$12+$B$2*'Станд.норм.распр.'!H10 -> 912.25248 | O18: =$E18*$B$11+$B$10+'Станд.норм.распр.'!I11*$B$12+$B$2*'Станд.норм.распр.'!I10 -> 910.45092 | ... Q18: =$E18*$B$11+$B$10+'Станд.норм.распр.'!K11*$B$12+$B$2*'Станд.норм.распр.'!K10 -> 908.80303
C19: X10 | D19: = | E19: 790 | G19: = | H19: =$E19*$B$11+$B$10+'Станд.норм.распр.'!B12*$B$12+$B$2*'Станд.норм.распр.'!B11 -> 792.93568 | I19: =$E19*$B$11+$B$10+'Станд.норм.распр.'!C12*$B$12+$B$2*'Станд.норм.распр.'!C11 -> 785.50879 | J19: =$E19*$B$11+$B$10+'Станд.норм.распр.'!D12*$B$12+$B$2*'Станд.норм.распр.'!D11 -> 793.39642 | K19: =$E19*$B$11+$B$10+'Станд.норм.распр.'!E12*$B$12+$B$2*'Станд.норм.распр.'!E11 -> 796.51379 | L19: =$E19*$B$11+$B$10+'Станд.норм.распр.'!F12*$B$12+$B$2*'Станд.норм.распр.'!F11 -> 793.66598 | M19: =$E19*$B$11+$B$10+'Станд.норм.распр.'!G12*$B$12+$B$2*'Станд.норм.распр.'!G11 -> 794.9968 | N19: =$E19*$B$11+$B$10+'Станд.норм.распр.'!H12*$B$12+$B$2*'Станд.норм.распр.'!H11 -> 800.03008 | O19: =$E19*$B$11+$B$10+'Станд.норм.распр.'!I12*$B$12+$B$2*'Станд.норм.распр.'!I11 -> 795.74376 | ... Q19: =$E19*$B$11+$B$10+'Станд.норм.распр.'!K12*$B$12+$B$2*'Станд.норм.распр.'!K11 -> 791.18753
